2020-05-22 20:45:44,876 ERROR: Exception on /user/jbh [GET] [in /Users/kevin/Desktop/program/dynamicblog/venv/lib/python3.8/site-packages/flask/app.py:1891]
Traceback (most recent call last):
  File "/Users/kevin/Desktop/program/dynamicblog/venv/lib/python3.8/site-packages/flask/app.py", line 2447, in wsgi_app
    response = self.full_dispatch_request()
  File "/Users/kevin/Desktop/program/dynamicblog/venv/lib/python3.8/site-packages/flask/app.py", line 1952, in full_dispatch_request
    rv = self.handle_user_exception(e)
  File "/Users/kevin/Desktop/program/dynamicblog/venv/lib/python3.8/site-packages/flask/app.py", line 1821, in handle_user_exception
    reraise(exc_type, exc_value, tb)
  File "/Users/kevin/Desktop/program/dynamicblog/venv/lib/python3.8/site-packages/flask/_compat.py", line 39, in reraise
    raise value
  File "/Users/kevin/Desktop/program/dynamicblog/venv/lib/python3.8/site-packages/flask/app.py", line 1950, in full_dispatch_request
    rv = self.dispatch_request()
  File "/Users/kevin/Desktop/program/dynamicblog/venv/lib/python3.8/site-packages/flask/app.py", line 1936, in dispatch_request
    return self.view_functions[rule.endpoint](**req.view_args)
  File "/Users/kevin/Desktop/program/dynamicblog/venv/lib/python3.8/site-packages/flask_login/utils.py", line 272, in decorated_view
    return func(*args, **kwargs)
  File "/Users/kevin/Desktop/program/dynamicblog/app/routes.py", line 58, in user
    return render_template('user.html', user=user, posts=posts.items,
  File "/Users/kevin/Desktop/program/dynamicblog/venv/lib/python3.8/site-packages/flask/templating.py", line 137, in render_template
    return _render(
  File "/Users/kevin/Desktop/program/dynamicblog/venv/lib/python3.8/site-packages/flask/templating.py", line 120, in _render
    rv = template.render(context)
  File "/Users/kevin/Desktop/program/dynamicblog/venv/lib/python3.8/site-packages/jinja2/environment.py", line 1090, in render
    self.environment.handle_exception()
  File "/Users/kevin/Desktop/program/dynamicblog/venv/lib/python3.8/site-packages/jinja2/environment.py", line 832, in handle_exception
    reraise(*rewrite_traceback_stack(source=source))
  File "/Users/kevin/Desktop/program/dynamicblog/venv/lib/python3.8/site-packages/jinja2/_compat.py", line 28, in reraise
    raise value.with_traceback(tb)
  File "/Users/kevin/Desktop/program/dynamicblog/app/templates/user.html", line 1, in top-level template code
    {% extends "base.html" %}
  File "/Users/kevin/Desktop/program/dynamicblog/venv/lib/python3.8/site-packages/jinja2/environment.py", line 832, in handle_exception
    reraise(*rewrite_traceback_stack(source=source))
  File "/Users/kevin/Desktop/program/dynamicblog/venv/lib/python3.8/site-packages/jinja2/_compat.py", line 28, in reraise
    raise value.with_traceback(tb)
  File "/Users/kevin/Desktop/program/dynamicblog/app/templates/base.html", line 55, in template
    <span id="{{ task.id }}-progress">{{ $.ajax(task.get_progress()) }}</span>
jinja2.exceptions.TemplateSyntaxError: unexpected char '$' at 2412
2020-05-22 20:46:23,412 INFO: Dynamicblog startup [in /Users/kevin/Desktop/program/dynamicblog/app/__init__.py:56]
2020-05-22 20:46:35,966 INFO: Dynamicblog startup [in ./app/__init__.py:56]
2020-05-22 20:47:27,743 INFO: Dynamicblog startup [in /Users/kevin/Desktop/program/dynamicblog/app/__init__.py:56]
2020-05-22 20:47:37,038 INFO: Dynamicblog startup [in ./app/__init__.py:56]
2020-05-22 20:48:54,209 INFO: Dynamicblog startup [in /Users/kevin/Desktop/program/dynamicblog/app/__init__.py:56]
2020-05-22 20:48:58,904 INFO: Dynamicblog startup [in ./app/__init__.py:56]
2020-05-24 20:03:42,507 INFO: Dynamicblog startup [in /Users/kevin/Desktop/program/dynamicblog/app/__init__.py:56]
